Workbook

Sheet Base_Alunos_ADI_2026
A1: ID | B1: RA | C1: nome | D1: serie | E1: ano_ingresso | F1: status | G1: aceitou_vaga | H1: cidade | I1: estado | J1: media_engajamento | K1: assinou_contrato | L1: acessou_email | M1: prova_unica_26.1 | N1: cadastro_atualizado | O1: presença_encontroclubes | P1: justificativa_ausência | Q1: acessou_discord
A2: 963372 | B2: 2024059447 | C2: Sandra | D2: 1° ano | E2: 2024 | F2: Ativo | G2: Sim | H2: Itu | I2: São Paulo | J2: 1 | K2: 1 | L2: 1 | M2: 1 | N2: 1 | O2: 1 | Q2: Sim
A3: 963454 | B3: 2024059937 | C3: Aparecida | D3: 1° ano | E3: 2024 | F3: Ativo | G3: Sim | H3: Campinas | I3: São Paulo | J3: 1 | K3: 1 | L3: 1 | M3: 1 | N3: 1 | O3: 1 | Q3: Sim
A4: 963536 | B4: 2024055535 | C4: Celia | D4: 1° ano | E4: 2024 | F4: Inativo | G4: Sim | H4: Rio de Janeiro | I4: Rio de Janeiro | J4: 0 | K4: 1 | L4: 1 | M4: 0 | N4: 1 | O4: 0 | P4: 0
A5: 963570 | B5: 2024054541 | C5: Heitor | D5: 1° ano | E5: 2024 | F5: Ativo | G5: Sim | H5: Salvador | I5: Bahia | J5: 0.8 | K5: 0 | L5: 1 | M5: 1 | N5: 1 | O5: 1 | Q5: Sim
A6: 963573 | B6: 2024052949 | C6: Danilo | D6: 1° ano | E6: 2024 | F6: Ativo | G6: Sim | H6: Joinville | I6: Santa Catarina | J6: 0 | K6: 0 | L6: 1 | M6: 1 | N6: 0 | O6: 0 | P6: 0 | Q6: Sim
A7: 963581 | B7: 2024057522 | C7: Bernardo | D7: 1° ano | E7: 2024 | F7: Ativo | G7: Sim | H7: Vargem Grande Paulista | I7: São Paulo | J7: 0.8 | K7: 0 | L7: 1 | M7: 1 | N7: 1 | O7: 1 | Q7: Sim
A8: 963655 | B8: 2024059770 | C8: Silvio | D8: 1° ano | E8: 2024 | F8: Ativo | G8: Sim | H8: Belo Horizonte | I8: Minas Gerais | J8: 0.8 | K8: 0 | L8: 1 | M8: 1 | N8: 1 | O8: 1 | Q8: Sim
A9: 963823 | B9: 2024059811 | C9: Marilene | D9: 1° ano | E9: 2024 | F9: Ativo | G9: Sim | H9: Joinville | I9: Santa Catarina | J9: 0 | K9: 0 | L9: 1 | M9: 0 | N9: 0 | O9: 0 | P9: 0
A10: 964156 | B10: 2024056554 | C10: Roberta | D10: 1° ano | E10: 2024 | F10: Ativo | G10: Sim | H10: Bela Cruz | I10: Ceará | J10: 0 | K10: 0 | L10: 1 | M10: 0 | N10: 0 | O10: 0 | P10: 0
A11: 964163 | B11: 2024058609 | C11: Milena | D11: 1° ano | E11: 2024 | F11: Ativo | G11: Sim | H11: Caieiras | I11: São Paulo | J11: 1 | K11: 1 | L11: 1 | M11: 1 | N11: 1 | O11: 1 | Q11: Sim
A12: 964279 | B12: 2024059473 | C12: Italo | D12: 1° ano | E12: 2024 | F12: Ativo | G12: Sim | H12: Cambota (Bela Cruz) | I12: Ceará | J12: 0.33333333 | K12: 0 | L12: 1 | M12: 0 | N12: 1 | O12: 0 | P12: 0 | Q12: Sim
A13: 964281 | B13: 2024053394 | C13: Luana | D13: 1° ano | E13: 2024 | F13: Ativo | G13: Sim | H13: Contagem | I13: Minas Gerais | J13: 0.9 | K13: 0.5 | L13: 1 | M13: 1 | N13: 1 | O13: 1
A14: 964326 | B14: 2024053866 | C14: Rosana | D14: 1° ano | E14: 2024 | F14: Ativo | G14: Sim | H14: Embu Guaçu | I14: São Paulo | J14: 1 | K14: 1 | L14: 1 | M14: 1 | N14: 1 | O14: 1
A15: 964358 | B15: 2024059739 | C15: Teresinha | D15: 1° ano | E15: 2024 | F15: Ativo | G15: Sim | H15: Rio de Janeiro | I15: Rio de Janeiro | J15: 0.9 | K15: 0.5 | L15: 1 | M15: 1 | N15: 1 | O15: 1 | Q15: Sim
A16: 964373 | B16: 2024054375 | C16: Rodrigo | D16: 1° ano | E16: 2024 | F16: Ativo | G16: Sim | H16: Rio de Janeiro | I16: Rio de Janeiro | J16: 0.8 | K16: 0 | L16: 1 | M16: 1 | N16: 1 | O16: 1 | Q16: Sim
A17: 964391 | B17: 2024052851 | C17: Orlando | D17: 1° ano | E17: 2024 | F17: Ativo | G17: Sim | H17: Rio de Janeiro | I17: Rio de Janeiro | J17: 1 | K17: 1 | L17: 1 | M17: 1 | N17: 1 | O17: 1 | Q17: Sim
A18: 964398 | B18: 2024051371 | C18: Joao | D18: 1° ano | E18: 2024 | F18: Ativo | G18: Sim | H18: Raul Soares | I18: Minas Gerais | J18: 0 | K18: 0 | L18: 1 | M18: 0 | N18: 0 | O18: 0 | P18: 0
A19: 964568 | B19: 2024057400 | C19: Cecilia | D19: 1° ano | E19: 2024 | F19: Ativo | G19: Sim | H19: Osasco | I19: São Paulo | J19: 0 | K19: 1 | L19: 1 | M19: 1 | N19: 0 | O19: 0 | P19: 0 | Q19: Sim
A20: 964596 | B20: 2024056003 | C20: Terezinha | D20: 1° ano | E20: 2024 | F20: Ativo | G20: Sim | H20: São Paulo | I20: São Paulo | J20: 0.8 | K20: 0 | L20: 1 | M20: 1 | N20: 1 | O20: 1 | Q20: Sim
A21: 964618 | B21: 2024055428 | C21: Alisson | D21: 1° ano | E21: 2024 | F21: Ativo | G21: Sim | H21: São José dos Campos | I21: São Paulo | J21: 0 | K21: 1 | L21: 1 | M21: 1 | N21: 0 | O21: 0 | P21: 0 | Q21: Sim
A22: 964647 | B22: 2024055478 | C22: Helio | D22: 1° ano | E22: 2024 | F22: Ativo | G22: Sim | H22: Belo Horizonte | I22: Minas Gerais | J22: 1 | K22: 1 | L22: 1 | M22: 1 | N22: 1 | O22: 1 | Q22: Sim
A23: 964713 | B23: 2024057489 | C23: Liliane | D23: 1° ano | E23: 2024 | F23: Ativo | G23: Sim | H23: São Paulo | I23: São Paulo | J23: 1 | K23: 1 | L23: 1 | M23: 1 | N23: 1 | O23: 1 | Q23: Sim
A24: 964771 | B24: 2024057780 | C24: Paulo | D24: 1° ano | E24: 2024 | F24: Ativo | G24: Sim | H24: Mauá | I24: São Paulo | J24: 1 | K24: 1 | L24: 1 | M24: 1 | N24: 1 | O24: 1 | Q24: Sim
A25: 964780 | B25: 2024051621 | C25: Breno | D25: 1° ano | E25: 2024 | F25: Ativo | G25: Sim | H25: Cotia | I25: São Paulo | J25: 0 | K25: 0 | L25: 1 | M25: 1 | N25: 0 | O25: 0 | P25: 0 | Q25: Sim
A26: 964793 | B26: 2024058553 | C26: Simone | D26: 1° ano | E26: 2024 | F26: Ativo | G26: Sim | H26: Sorocaba | I26: São Paulo | J26: 1 | K26: 1 | L26: 1 | M26: 1 | N26: 1 | O26: 1 | Q26: Sim
A27: 964947 | B27: 2024052675 | C27: Sheila | D27: 1° ano | E27: 2024 | F27: Ativo | G27: Sim | H27: São José dos Campos | I27: São Paulo | J27: 0 | K27: 0 | L27: 1 | M27: 0 | N27: 0 | O27: 0 | P27: 0 | Q27: Sim
A28: 964991 | B28: 2024051003 | C28: Josue | D28: 1° ano | E28: 2024 | F28: Inativo | G28: Sim | H28: Belo Horizonte | I28: Minas Gerais | J28: 0 | K28: 1 | L28: 1 | M28: 0 | N28: 0 | O28: 0 | P28: 0
A29: 965010 | B29: 2024054164 | C29: Margarida | D29: 1° ano | E29: 2024 | F29: Ativo | G29: Sim | H29: São José dos Campos | I29: São Paulo | J29: 0.66666667 | K29: 1 | L29: 1 | M29: 1 | N29: 1 | O29: 0 | P29: 0 | Q29: Sim
A30: 965155 | B30: 2024053713 | C30: Giovana | D30: 1° ano | E30: 2024 | F30: Ativo | G30: Sim | H30: São Paulo | I30: São Paulo | J30: 0 | K30: 0 | L30: 1 | M30: 0 | N30: 0 | O30: 0 | P30: 0
A31: 965216 | B31: 2024058959 | C31: Joaquim | D31: 1° ano | E31: 2024 | F31: Ativo | G31: Sim | H31: Betim | I31: Minas Gerais | J31: 0 | K31: 0 | L31: 1 | M31: 1 | N31: 0 | O31: 0 | P31: 0
A32: 965284 | B32: 2024059446 | C32: Rosa | D32: 1° ano | E32: 2024 | F32: Ativo | G32: Sim | H32: São Paulo | I32: São Paulo | J32: 1 | K32: 1 | L32: 1 | M32: 1 | N32: 1 | O32: 1 | Q32: Sim
A33: 965302 | B33: 2024051753 | C33: Gabriel | D33: 1° ano | E33: 2024 | F33: Ativo | G33: Sim | H33: São Paulo | I33: São Paulo | J33: 1 | K33: 1 | L33: 1 | M33: 1 | N33: 1 | O33: 1 | Q33: Sim
A34: 965304 | B34: 2024055204 | C34: Gael | D34: 1° ano | E34: 2024 | F34: Ativo | G34: Sim | H34: São Paulo | I34: São Paulo | J34: 0 | K34: 0 | L34: 1 | M34: 0 | N34: 0 | O34: 0 | P34: 0
A35: 965376 | B35: 2024051444 | C35: Moises | D35: 1° ano | E35: 2024 | F35: Ativo | G35: Sim | H35: Rio de Janeiro | I35: Rio de Janeiro | J35: 0.66666667 | K35: 1 | L35: 1 | M35: 1 | N35: 1 | O35: 0 | P35: 0 | Q35: Sim
A36: 965437 | B36: 2024052265 | C36: Marcela | D36: 1° ano | E36: 2024 | F36: Ativo | G36: Sim | H36: Rio de Janeiro | I36: Rio de Janeiro | J36: 0.5 | K36: 0 | L36: 1 | M36: 1 | N36: 1 | O36: 0 | P36: 0 | Q36: Sim
A37: 965496 | B37: 2024052046 | C37: Angelo | D37: 1° ano | E37: 2024 | F37: Ativo | G37: Sim | H37: Vila Velha | I37: Espírito Santo | J37: 0 | K37: 0.5 | L37: 1 | M37: 0 | N37: 0 | O37: 0 | P37: 0
A38: 968025 | B38: 2026074095 | C38: Sueli | D38: 1° ano | E38: 2026 | F38: Ativo | G38: Sim | H38: São Miguel dos Campos | I38: Alagoas | J38: 0.66666667 | K38: 1 | L38: 1 | M38: 1 | N38: 1 | O38: 0 | P38: 0 | Q38: Sim
A39: 968088 | B39: 2026073286 | C39: Augusto | D39: 1° ano | E39: 2026 | F39: Ativo | G39: Sim | H39: São Paulo | I39: São Paulo | J39: 0 | K39: 1 | L39: 0 | M39: 0 | N39: 0 | O39: 0 | P39: 0 | Q39: Sim
A40: 968263 | B40: 2026077641 | C40: Beatriz | D40: 1° ano | E40: 2026 | F40: Ativo | G40: Sim | H40: São José dos Campos | I40: São Paulo | J40: 0 | K40: 1 | L40: 1 | M40: 1 | N40: 0 | O40: 0 | P40: 0 | Q40: Sim
...

Sheet Base_PS_2026
A1: ID | B1: nome | C1: serie | D1: origem | E1: genero | F1: etnia | G1: acesso_plataforma | H1: progresso_aulas | I1: cidade | J1: estado | K1: regiao | L1: fez_PD | M1: dentro_criterio_PD | N1: nota_MAT | O1: cluster_nota_MAT
A2: 968025 | B2: Sueli | C2: 9° ano | D2: Processo Seletivo - 1° Leva | E2: Feminino | F2: Parda | G2: Sim | H2: 0.0645 | I2: São Miguel dos Campos | J2: Alagoas | K2: Nordeste | L2: Sim | M2: Sim | N2: 94.165567 | O2: Entre 90 e 100
A3: 968088 | B3: Augusto | C3: 9° ano | D3: Processo Seletivo - 1° Leva | E3: Feminino | F3: Parda | G3: Sim | H3: 0.9032 | I3: São Paulo | J3: São Paulo | K3: Sudeste | L3: Sim | M3: Sim | N3: 83.314382 | O3: Entre 80 e 90
A4: 968263 | B4: Beatriz | C4: 9° ano | D4: Processo Seletivo - 1° Leva | E4: Masculino | F4: Branca | G4: Sim | H4: 0.8065 | I4: São José dos Campos | J4: São Paulo | K4: Sudeste | L4: Sim | M4: Sim | N4: 91.213334 | O4: Entre 90 e 100
A5: 968407 | B5: Marli | C5: 9° ano | D5: Processo Seletivo - 1° Leva | E5: Feminino | F5: Branca | G5: Sim | H5: 1 | I5: São José dos Campos | J5: São Paulo | K5: Sudeste | L5: Sim | M5: Sim | N5: 93.554109 | O5: Entre 90 e 100
A6: 968625 | B6: Levi | C6: 9° ano | D6: Processo Seletivo - 1° Leva | E6: Feminino | F6: Branca | G6: Sim | H6: 1 | I6: São Paulo | J6: São Paulo | K6: Sudeste | L6: Sim | M6: Sim | N6: 84.701255 | O6: Entre 80 e 90
A7: 969951 | B7: Reginaldo | C7: 7º ano | D7: Processo Seletivo - 1° Leva | E7: Masculino | F7: Parda | G7: Sim | H7: 1 | I7: São José da Lapa | J7: Minas Gerais | K7: Sudeste | L7: Sim | M7: Sim | N7: 75.542319 | O7: Entre 70 e 80
A8: 970117 | B8: Gisele | C8: 9° ano | D8: Processo Seletivo - 1° Leva | E8: Feminino | F8: Branca | G8: Sim | H8: 1 | I8: Rio de Janeiro | J8: Rio de Janeiro | K8: Sudeste | L8: Sim | M8: Sim | N8: 82.181806 | O8: Entre 80 e 90
A9: 970309 | B9: Fabricio | C9: 9° ano | D9: Processo Seletivo - 1° Leva | E9: Feminino | F9: Branca | G9: Sim | H9: 1 | I9: São Paulo | J9: São Paulo | K9: Sudeste | L9: Sim | M9: Sim | N9: 83.685234 | O9: Entre 80 e 90
A10: 970370 | B10: Pedro | C10: 8° ano | D10: Processo Seletivo - 1° Leva | E10: Masculino | F10: Parda | G10: Sim | H10: 1 | I10: Rio de Janeiro | J10: Rio de Janeiro | K10: Sudeste | L10: Sim | M10: Sim | N10: 84.477367 | O10: Entre 80 e 90
A11: 971600 | B11: Ester | C11: 9° ano | D11: Processo Seletivo - 1° Leva | E11: Feminino | F11: Parda | G11: Sim | H11: 1 | I11: Salvador | J11: Bahia | K11: Nordeste | L11: Sim | M11: Sim | N11: 109.15008 | O11: Maior que 100
A12: 971613 | B12: Nathalia | C12: 9° ano | D12: Processo Seletivo - 1° Leva | E12: Feminino | F12: Parda | G12: Sim | H12: 1 | I12: Rio de Janeiro | J12: Rio de Janeiro | K12: Sudeste | L12: Sim | M12: Sim | N12: 88.769049 | O12: Entre 80 e 90
A13: 973603 | B13: Heloisa | C13: 7º ano | D13: Processo Seletivo - 1° Leva | E13: Masculino | F13: Preta | G13: Sim | H13: 0.9677 | I13: Joinville | J13: Santa Catarina | K13: Sul | L13: Sim | M13: Sim | N13: 71.564897 | O13: Entre 70 e 80
... A295: 992058 | B295: Gabriele | C295: 9° ano | D295: Processo Seletivo - 2° Leva | E295: Feminino | F295: Branca | G295: Sim | H295: 1 | I295: São José dos Campos | J295: São Paulo | K295: Sudeste | L295: Sim | M295: Sim | N295: 88.661992 | O295: Entre 80 e 90
A296: MP102 | B296: Luiza | C296: 7º ano | D296: Missão Planeta | E296: Masculino | F296: Parda | G296: Sim | H296: 0.0303 | I296: Açailandia | J296: Maranhão | K296: Nordeste | L296: Sim | M296: Sim | N296: 87.893527 | O296: Entre 80 e 90
A297: MP103 | B297: Edilson | C297: 7º ano | D297: Missão Planeta | E297: Feminino | F297: Parda | G297: Sim | H297: 0.5152 | I297: Penedo | J297: Alagoas | K297: Nordeste | L297: Sim | M297: Não | N297: 79.674198 | O297: Entre 70 e 80
A298: MP107 | B298: Vera | C298: 7º ano | D298: Missão Planeta | E298: Masculino | F298: Parda | G298: Sim | H298: 0.6667 | I298: Coruripe | J298: Alagoas | K298: Nordeste | L298: Sim | M298: Sim | N298: 102.32415 | O298: Maior que 100
A299: MP108 | B299: Rosilene | C299: 7º ano | D299: Missão Planeta | E299: Feminino | F299: Parda | G299: Sim | H299: 1 | I299: Coruripe | J299: Alagoas | K299: Nordeste | L299: Sim | M299: Sim | N299: 76.626675 | O299: Entre 70 e 80
A300: MP133 | B300: Clara | C300: 7º ano | D300: Missão Planeta | E300: Feminino | F300: Branca | G300: Sim | H300: 0.8788 | I300: Rio de Janeiro | J300: Rio de Janeiro | K300: Sudeste | L300: Sim | M300: Sim | N300: 63.313246 | O300: Entre 60 e 70
A301: MP134 | B301: Luciene | C301: 9° ano | D301: Missão Planeta | E301: Feminino | F301: Branca | G301: Sim | H301: 1 | I301: Maraú | J301: Bahia | K301: Nordeste | L301: Sim | M301: Sim | N301: 91.732691 | O301: Entre 90 e 100
A302: MP135 | B302: Michele | C302: 7º ano | D302: Missão Planeta | E302: Masculino | F302: Parda | G302: Sim | H302: 0.9394 | I302: Rio de Janeiro | J302: Rio de Janeiro | K302: Sudeste | L302: Sim | M302: Sim | N302: 65.794849 | O302: Entre 60 e 70
A303: MP138 | B303: Thais | C303: 7º ano | D303: Missão Planeta | E303: Feminino | F303: Parda | G303: Sim | H303: 1 | I303: São Paulo | J303: São Paulo | K303: Sudeste | L303: Sim | M303: Sim | N303: 61.455211 | O303: Entre 60 e 70
A304: MP139 | B304: Ruan | C304: 9° ano | D304: Missão Planeta | E304: Feminino | F304: Branca | G304: Sim | H304: 0.0303 | I304: Ilhéus | J304: Bahia | K304: Nordeste | L304: Sim | M304: Sim | N304: 99.170556 | O304: Entre 90 e 100
A305: MP15 | B305: Vagner | C305: 7º ano | D305: Missão Planeta | E305: Masculino | F305: Parda | G305: Sim | H305: 0.7576 | I305: Embu das Artes | J305: São Paulo | K305: Sudeste | L305: Sim | M305: Sim | N305: 62.266651 | O305: Entre 60 e 70
A306: MP23 | B306: Everton | C306: 7º ano | D306: Missão Planeta | E306: Masculino | F306: Branca | G306: Sim | H306: 1 | I306: Belo Horizonte | J306: Minas Gerais | K306: Sudeste | L306: Sim | M306: Sim | N306: 88.545984 | O306: Entre 80 e 90
A307: MP25 | B307: Rafaela | C307: 7º ano | D307: Missão Planeta | E307: Masculino | F307: Parda | G307: Sim | H307: 1 | I307: Uirapuru | J307: Goiás | K307: Centro-Oeste | L307: Sim | M307: Não | N307: 84.628379 | O307: Entre 80 e 90
... A310: MP39 | B310: Sabrina | C310: 7º ano | D310: Missão Planeta | E310: Masculino | F310: Branca | G310: Sim | H310: 0.7576 | I310: Curitiba | J310: Paraná | K310: Sul | L310: Sim | M310: Sim | N310: 73.43763 | O310: Entre 70 e 80
A311: MP51 | B311: Jefferson | C311: 9° ano | D311: Missão Planeta | E311: Feminino | F311: Parda | G311: Sim | H311: 0.8182 | I311: Rio de Janeiro | J311: Rio de Janeiro | K311: Sudeste | L311: Não | M311: -- | N311: -- | O311: --
A312: MP52 | B312: Lucilene | C312: 7º ano | D312: Missão Planeta | E312: Masculino | F312: Parda | G312: Sim | H312: 0.7576 | I312: Rio de Janeiro | J312: Rio de Janeiro | K312: Sudeste | L312: Sim | M312: Sim | N312: 68.266039 | O312: Entre 60 e 70
A313: MP54 | B313: Nilson | C313: 9° ano | D313: Missão Planeta | E313: Feminino | F313: Branca | G313: Sim | H313: 1 | I313: Rio de Janeiro | J313: Rio de Janeiro | K313: Sudeste | L313: Sim | M313: Não | N313: 67.251184 | O313: Entre 60 e 70
A314: MP59 | B314: Marina | C314: 9° ano | D314: Missão Planeta | E314: Feminino | F314: Parda | G314: Sim | H314: 0.0303 | I314: Ilhéus | J314: Bahia | K314: Nordeste | L314: Sim | M314: Sim | N314: 100.89146 | O314: Maior que 100
A315: MP62 | B315: Lara | C315: 9° ano | D315: Missão Planeta | E315: Masculino | F315: Branca | G315: Sim | H315: 1 | I315: Caraguatatuba | J315: São Paulo | K315: Sudeste | L315: Sim | M315: Sim | N315: 84.539277 | O315: Entre 80 e 90
A316: MP66 | B316: Raiane | C316: 7º ano | D316: Missão Planeta | E316: Feminino | F316: Branca | G316: Sim | H316: 1 | I316: Jundiaí | J316: São Paulo | K316: Sudeste | L316: Sim | M316: Sim | N316: 97.313121 | O316: Entre 90 e 100
A317: MP70 | B317: Josefa | C317: 9° ano | D317: Missão Planeta | E317: Masculino | F317: Parda | G317: Sim | H317: 1 | I317: Franca | J317: São Paulo | K317: Sudeste | L317: Sim | M317: Sim | N317: 78.886649 | O317: Entre 70 e 80
A318: MP80 | B318: Pablo | C318: 7º ano | D318: Missão Planeta | E318: Feminino | F318: Parda | G318: Sim | H318: 0.7576 | I318: Rio de Janeiro | J318: Rio de Janeiro | K318: Sudeste | L318: Sim | M318: Sim | N318: 71.482354 | O318: Entre 70 e 80
A319: MP88 | B319: Manuel | C319: 9° ano | D319: Missão Planeta | E319: Feminino | F319: Parda | G319: Sim | H319: 1 | I319: Monte Azul | J319: Minas Gerais | K319: Sudeste | L319: Sim | M319: Sim | N319: 80.936465 | O319: Entre 80 e 90
A320: MP90 | B320: Emanuel | C320: 9° ano | D320: Missão Planeta | E320: Feminino | F320: Sem declaração | G320: Sim | H320: 1 | I320: Taboao da Serra | J320: São Paulo | K320: Sudeste | L320: Sim | M320: Sim | N320: 84.700644 | O320: Entre 80 e 90

Sheet Base_Alunos_Veteranos
A1: ID | B1: RA | C1: nome | D1: etnia | E1: genero | F1: estado | G1: cidade
A2: 963372 | B2: 2024059447 | C2: {=xlookup(B2,Base_Alunos_ADI_2026!B:B,Base_Alunos_ADI_2026!C:C)} -> #NAME? | D2: Branca | E2: Feminino | F2: São Paulo (SP) | G2: Itu
A3: 963454 | B3: 2024059937 | C3: {=xlookup(B3,Base_Alunos_ADI_2026!B:B,Base_Alunos_ADI_2026!C:C)} -> #NAME? | D3: Parda | E3: Feminino | F3: São Paulo (SP) | G3: Campinas
A4: 963536 | B4: 2024055535 | C4: {=xlookup(B4,Base_Alunos_ADI_2026!B:B,Base_Alunos_ADI_2026!C:C)} -> #NAME? | D4: Branca | E4: Feminino | F4: Rio de Janeiro (RJ) | G4: Rio de Janeiro
A5: 963570 | B5: 2024054541 | C5: {=xlookup(B5,Base_Alunos_ADI_2026!B:B,Base_Alunos_ADI_2026!C:C)} -> #NAME? | D5: Parda | E5: Feminino | F5: Bahia (BA) | G5: Salvador
A6: 963573 | B6: 2024052949 | C6: {=xlookup(B6,Base_Alunos_ADI_2026!B:B,Base_Alunos_ADI_2026!C:C)} -> #NAME? | D6: Branca | E6: Masculino | F6: Santa Catarina (SC) | G6: Joinville
A7: 963581 | B7: 2024057522 | C7: {=xlookup(B7,Base_Alunos_ADI_2026!B:B,Base_Alunos_ADI_2026!C:C)} -> #NAME? | D7: Branca | E7: Feminino | F7: São Paulo (SP) | G7: Vargem Grande Paulista
A8: 963655 | B8: 2024059770 | C8: {=xlookup(B8,Base_Alunos_ADI_2026!B:B,Base_Alunos_ADI_2026!C:C)} -> #NAME? | D8: Branca | E8: Feminino | F8: Minas Gerais (MG) | G8: Belo Horizonte
A9: 963823 | B9: 2024059811 | C9: {=xlookup(B9,Base_Alunos_ADI_2026!B:B,Base_Alunos_ADI_2026!C:C)} -> #NAME? | D9: Branca | E9: Masculino | F9: Santa Catarina (SC) | G9: Joinville
A10: 964156 | B10: 2024056554 | C10: {=xlookup(B10,Base_Alunos_ADI_2026!B:B,Base_Alunos_ADI_2026!C:C)} -> #NAME? | D10: Branca | E10: Feminino | F10: Ceará (CE) | G10: Bela Cruz
A11: 964163 | B11: 2024058609 | C11: {=xlookup(B11,Base_Alunos_ADI_2026!B:B,Base_Alunos_ADI_2026!C:C)} -> #NAME? | D11: Branca | E11: Masculino | F11: São Paulo (SP) | G11: Caieiras
A12: 964279 | B12: 2024059473 | C12: {=xlookup(B12,Base_Alunos_ADI_2026!B:B,Base_Alunos_ADI_2026!C:C)} -> #NAME? | D12: Parda | E12: Feminino | F12: Ceará (CE) | G12: Cambota (Bela Cruz)
A13: 964281 | B13: 2024053394 | C13: {=xlookup(B13,Base_Alunos_ADI_2026!B:B,Base_Alunos_ADI_2026!C:C)} -> #NAME? | D13: Branca | E13: Feminino | F13: Minas Gerais (MG) | G13: Contagem
... A37: 965496 | B37: 2024052046 | C37: {=xlookup(B37,Base_Alunos_ADI_2026!B:B,Base_Alunos_ADI_2026!C:C)} -> #NAME? | D37: Parda | E37: Masculino | F37: Espírito Santo (ES) | G37: Vila Velha
